<sdf version="1.9">
<model name="arm" canonical_link="root.000">
  <joint name="joint0" type="revolute">
    <pose relative_to="root.000">0.00089 -0.00025 0.00205 -3.14159 -0.00000 1.57062</pose>
    <parent>root.000</parent>
    <child>link1</child>
    <axis>
      <limit>
        <lower>-3.14000</lower>
        <upper>3.14000</upper>
        <effort>0.00000</effort>
        <velocity>0.00000</velocity>
      </limit>
      <xyz>0.00000 0.00000 -1.00000</xyz>
    </axis>
  </joint>
  <joint name="joint1" type="revolute">
    <pose relative_to="link1">-0.00012 -0.00014 -0.02442 1.57082 -0.00009 -1.57089</pose>
    <parent>link1</parent>
    <child>link2</child>
    <axis>
      <limit>
        <lower>-3.14000</lower>
        <upper>3.14000</upper>
        <effort>0.00000</effort>
        <velocity>0.00000</velocity>
      </limit>
      <xyz>0.00000 0.00000 -1.00000</xyz>
    </axis>
  </joint>
  <joint name="joint3" type="revolute">
    <pose relative_to="link2">-0.09876 0.00001 -0.00008 0.00000 0.00000 0.00000</pose>
    <parent>link2</parent>
    <child>link3</child>
    <axis>
      <limit>
        <lower>-3.14000</lower>
        <upper>3.14000</upper>
        <effort>0.00000</effort>
        <velocity>0.00000</velocity>
      </limit>
      <xyz>0.00000 0.00000 -1.00000</xyz>
    </axis>
  </joint>
  <joint name="joint4" type="revolute">
    <pose relative_to="link3">-0.09983 0.00001 -0.00027 -0.00000 -0.00000 -0.00000</pose>
    <parent>link3</parent>
    <child>link4</child>
    <axis>
      <limit>
        <lower>-3.14000</lower>
        <upper>3.14000</upper>
        <effort>0.00000</effort>
        <velocity>0.00000</velocity>
      </limit>
      <xyz>0.00000 0.00000 -1.00000</xyz>
    </axis>
  </joint>
  <link name="link1">
    <inertial>
      <inertia>
        <ixx>0.00100</ixx>
        <ixy>-0.00000</ixy>
        <ixz>-0.00000</ixz>
        <iyy>0.00100</iyy>
        <iyz>0.00000</iyz>
        <izz>0.00100</izz>
      </inertia>
      <pose relative_to="link1">-0.00000 -0.00000 -0.00000 0.00000 0.00000 0.00000</pose>
      <mass>0.20000</mass>
    </inertial>
  </link>
  <link name="link2">
    <inertial>
      <inertia>
        <ixx>0.00100</ixx>
        <ixy>-0.00000</ixy>
        <ixz>0.00000</ixz>
        <iyy>0.00100</iyy>
        <iyz>-0.00000</iyz>
        <izz>0.00100</izz>
      </inertia>
      <pose relative_to="link2">-0.00000 0.00000 0.00000 0.00000 0.00000 0.00000</pose>
      <mass>0.20000</mass>
    </inertial>
    <visual name="link_2">
      <pose relative_to="link2">-0.00000 0.00000 -0.00000 -0.00002 -0.00000 0.00000</pose>
      <geometry>
        <mesh>
          <uri>../meshes/stl/Cube.010.stl</uri>
          <scale>1.00000 1.00000 1.00000</scale>
        </mesh>
      </geometry>
    </visual>
  </link>
  <link name="link3">
    <inertial>
      <inertia>
        <ixx>0.00100</ixx>
        <ixy>0.00000</ixy>
        <ixz>0.00000</ixz>
        <iyy>0.00100</iyy>
        <iyz>0.00000</iyz>
        <izz>0.00100</izz>
      </inertia>
      <pose relative_to="link3">-0.00000 -0.00000 0.00000 0.00000 0.00000 0.00000</pose>
      <mass>0.20000</mass>
    </inertial>
    <visual name="link_3">
      <pose relative_to="link3">-0.00000 -0.00000 -0.00000 -0.00002 -0.00000 0.00000</pose>
      <geometry>
        <mesh>
          <uri>../meshes/stl/Cube.013.stl</uri>
          <scale>1.00000 1.00000 1.00000</scale>
        </mesh>
      </geometry>
    </visual>
  </link>
  <link name="link4">
    <visual name="link_4">
      <pose relative_to="link4">-0.00000 0.00000 0.00000 -0.00002 -0.00000 0.00000</pose>
      <geometry>
        <mesh>
          <uri>../meshes/stl/Cube.014.stl</uri>
          <scale>1.00000 1.00000 1.00000</scale>
        </mesh>
      </geometry>
    </visual>
  </link>
  <link name="root.000">
    <visual name="base">
      <pose relative_to="root.000">-0.00000 0.00000 0.00000 0.00000 0.00000 -0.00000</pose>
      <geometry>
        <mesh>
          <uri>../meshes/stl/Cube.018.stl</uri>
          <scale>1.00000 1.00000 1.00000</scale>
        </mesh>
      </geometry>
    </visual>
  </link>
  <plugin filename="gz-sim-joint-position-controller-system" name="gz::sim::systems::JointPositionController">
    <joint_name>joint0</joint_name>
    <p_gain>20.00000</p_gain>
    <i_gain>0.00000</i_gain>
    <d_gain>0.00000</d_gain>
  </plugin>
  <plugin filename="gz-sim-joint-position-controller-system" name="gz::sim::systems::JointPositionController">
    <joint_name>joint1</joint_name>
    <p_gain>20.00000</p_gain>
    <i_gain>0.00000</i_gain>
    <d_gain>0.00000</d_gain>
  </plugin>
  <plugin filename="gz-sim-joint-position-controller-system" name="gz::sim::systems::JointPositionController">
    <joint_name>joint3</joint_name>
    <p_gain>20.00000</p_gain>
    <i_gain>0.00000</i_gain>
    <d_gain>0.00000</d_gain>
  </plugin>
  <plugin filename="gz-sim-joint-position-controller-system" name="gz::sim::systems::JointPositionController">
    <joint_name>joint4</joint_name>
    <p_gain>20.00000</p_gain>
    <i_gain>0.00000</i_gain>
    <d_gain>0.00000</d_gain>
  </plugin>
</model>
</sdf>