<?xml version="1.0"?>
<robot xmlns:xacro="http://www.ros.org/wiki/xacro">

  <xacro:macro name="rrbot" params="parent prefix *origin">
    <joint name="joint0" type="revolute">
      <limit lower="-3.14000" upper="3.14000" effort="0.00000" velocity="0.00000" />
      <origin rpy="-3.14159 -0.00000 1.57062" xyz="0.00089 -0.00025 0.00205" />
      <parent link="root.000" />
      <child link="link1" />
      <axis xyz="0.00000 0.00000 -1.00000" />
    </joint>
    <joint name="joint1" type="revolute">
      <limit lower="-3.14000" upper="3.14000" effort="0.00000" velocity="0.00000" />
      <origin rpy="1.57082 -0.00009 -1.57089" xyz="-0.00012 -0.00014 -0.02442" />
      <parent link="link1" />
      <child link="link2" />
      <axis xyz="0.00000 0.00000 -1.00000" />
    </joint>
    <joint name="joint3" type="revolute">
      <limit lower="-3.14000" upper="3.14000" effort="0.00000" velocity="0.00000" />
      <origin rpy="0.00000 0.00000 0.00000" xyz="-0.09876 0.00001 -0.00008" />
      <parent link="link2" />
      <child link="link3" />
      <axis xyz="0.00000 0.00000 -1.00000" />
    </joint>
    <joint name="joint4" type="revolute">
      <limit lower="-3.14000" upper="3.14000" effort="0.00000" velocity="0.00000" />
      <origin rpy="-0.00000 -0.00000 -0.00000" xyz="-0.09983 0.00001 -0.00027" />
      <parent link="link3" />
      <child link="link4" />
      <axis xyz="0.00000 0.00000 -1.00000" />
    </joint>
    <link name="link1">
      <inertial>
        <inertia ixx="0.00100" ixy="-0.00000" ixz="-0.00000" iyy="0.00100" iyz="0.00000"
          izz="0.00100" />
        <origin rpy="0.00000 0.00000 0.00000" xyz="-0.00000 -0.00000 -0.00000" />
        <mass value="0.20000" />
      </inertial>
    </link>
    <link name="link2">
      <inertial>
        <inertia ixx="0.00100" ixy="-0.00000" ixz="0.00000" iyy="0.00100" iyz="-0.00000"
          izz="0.00100" />
        <origin rpy="0.00000 0.00000 0.00000" xyz="-0.00000 0.00000 0.00000" />
        <mass value="0.20000" />
      </inertial>
      <visual name="link_2">
        <origin rpy="-0.00002 -0.00000 0.00000" xyz="-0.00000 0.00000 -0.00000" />
        <geometry>
          <mesh filename="file://$(find ros2_control_demo_example_9)/meshes/stl/Cube.010.stl" scale="1.00000 1.00000 1.00000" />
        </geometry>
      </visual>
    </link>
    <link name="link3">
      <inertial>
        <inertia ixx="0.00100" ixy="0.00000" ixz="0.00000" iyy="0.00100" iyz="0.00000" izz="0.00100" />
        <origin rpy="0.00000 0.00000 0.00000" xyz="-0.00000 -0.00000 0.00000" />
        <mass value="0.20000" />
      </inertial>
      <visual name="link_3">
        <origin rpy="-0.00002 -0.00000 0.00000" xyz="-0.00000 -0.00000 -0.00000" />
        <geometry>
          <mesh filename="file://$(find ros2_control_demo_example_9)/meshes/stl/Cube.013.stl" scale="1.00000 1.00000 1.00000" />
        </geometry>
      </visual>
    </link>
    <link name="link4">
      <inertial>
        <inertia ixx="0.00100" ixy="0.00000" ixz="0.00000" iyy="0.00100" iyz="0.00000" izz="0.00100" />
        <origin rpy="0.00000 0.00000 0.00000" xyz="-0.00000 -0.00000 0.00000" />
        <mass value="0.20000" />
      </inertial>
      <visual name="link_4">
        <origin rpy="-0.00002 -0.00000 0.00000" xyz="-0.00000 0.00000 0.00000" />
        <geometry>
          <mesh filename="file://$(find ros2_control_demo_example_9)/meshes/stl/Cube.014.stl" scale="1.00000 1.00000 1.00000" />
        </geometry>
      </visual>
    </link>
    <link name="root.000">
      <visual name="base">
        <origin rpy="0.00000 0.00000 -0.00000" xyz="-0.00000 0.00000 0.00000" />
        <geometry>
          <mesh filename="file://$(find ros2_control_demo_example_9)/meshes/stl/Cube.018.stl" scale="1.00000 1.00000 1.00000" />
        </geometry>
      </visual>
    </link>

    <joint name="base_joint" type="fixed">
      <origin xyz="0 0 0" rpy="0 0 0" />
      <parent link="${parent}" />
      <child link="root.000" />
    </joint>

    </xacro:macro>
</robot>